Workbook

Sheet README
A1: OpenTwin Anchor Layer, consolidated workbook
A2: Version 3.0 · 28 July 2026 · supersedes the 2026-07-27 and 2026-07 FineTuned workbooks
A4: Punch line | C4: Biomarker measurement first, interpretation second. A quantity must be measurable, in a declared unit, against an interval, before any interpretive layer may touch it.
A6: HEADLINE NUMBERS
A7: Core markers in the anchor set | B7: =COUNTA(Anchor_Core_Set!$A$2:$A$68) -> 67 | C7: Unchanged across both source workbooks.
A8: Markers with no blocking or open flag | B8: =COUNTIF(Anchor_Core_Set!$T$2:$T$68,"none") -> 58 | C8: Ready to build against today.
A9: Markers with a BLOCKING flag | B9: =SUMPRODUCT(--ISNUMBER(SEARCH("BLOCKING",Anchor_Core_Set!$T$2:$T$68))) -> 3 | C9: LOINC property disagrees with the declared unit. Needs a decision, see Data_Quality_Findings F-01 to F-03.
A10: Markers with at least one interval on file | B10: =COUNTIF(Anchor_Core_Set!$V$2:$V$68,"interval_on_file") -> 31 | C10: Interpretation is possible for these today.
A11: Markers with no interval, model abstains | B11: =COUNTIF(Anchor_Core_Set!$V$2:$V$68,"no_interval_abstain") -> 36 | C11: NOT a defect. Per SAD invariant 3 a null interval means the model abstains and says why.
A12: Candidate reference intervals recorded | B12: =COUNTA(Reference_Intervals!$A$2:$A$99) -> 98 | C12: Candidates, not canonical values. Many markers carry more than one.
A13: Region enum size (closed) | B13: =COUNTA(Region_Enum!$A$2:$A$26) -> 25 | C13: Adding a region is a contract change and needs an ADR.
A14: Terminology codes still UNVERIFIED | B14: =COUNTIF(Anchor_Core_Set!$F$2:$F$68,"UNVERIFIED") -> 67 | C14: The review work queue. CI stays red until a named human signs these off.
A15: Open findings | B15: =COUNTIF(Data_Quality_Findings!$G$2:$G$17,"OPEN") -> 9 | C15: See Data_Quality_Findings.
A17: SHEETS
A18: Anchor_Core_Set | B18: 67 rows | C18: The core set, with UCUM units, region ids and blocking flags. The two right-hand columns are formulas driven off Reference_Intervals.
A19: Region_Enum | B19: 25 rows | C19: Closed vocabulary of body regions, split into anatomical and system. Proposed SNOMED and UBERON bindings, all UNVERIFIED.
A20: Organ_Mapping_Crosswalk | B20: 26 rows | C20: How each free-text organ_mapping token resolves. Three tokens are proposed for retirement.
A21: Reference_Intervals | B21: 98 rows | C21: Candidate intervals with issuer, issuer kind, source URL and retrieval date. Interpretive bands are tagged separately.
A22: LOINC_Map | B22: 69 rows | C22: Codes with loinc.org URLs and the review-record path each one needs.
A23: Data_Quality_Findings | B23: 16 rows | C23: Every known defect and open question, with severity, owner and status.
A24: C3_Audit | B24: 20 rows | C24: Guideline anchoring pass, carried over unchanged.
A25: Panel_Decomposition | B25: 21 rows | C25: How the composite panels were decomposed, carried over unchanged.
A26: Exclusions | B26: 372 rows | C26: The negative space. Why 355 of 422 markers are not in the core set.
A27: Change_Log | B27: 9 rows | C27: What changed in this version and why.
A29: PROVENANCE
A30: Reference_Intervals | B30: 2026_07_27_OpenTwin_AnchorLayer.xlsx | C30: Taken from the earlier file. The FineTuned version lost the parsed low, high and population columns: 98 populated rows became 0. See finding F-04.
A31: Everything else | B31: 2026_07_OpenTwin_AnchorLayer_FineTuned.xlsx | C31: The later file added organ_mapping, LOINC_Map, C3_Audit, Panel_Decomposition and Exclusions.
A32: Interval issuers | B32: IMD Berlin Leistungsverzeichnis (12.02.2025); IMD Berlin-Potsdam Referenzbereiche (28.09.2015) | C32: URLs and retrieval date 2026-07-12 taken from the Landscape Review reference list.
A33: UCUM mapping | B33: Added here | C33: Hypothesis only. Must be validated against a real UCUM grammar library in CI before it is trusted.
A34: Region enum and codes | B34: Proposed here | C34: SNOMED and UBERON identifiers are proposed and UNVERIFIED. They are not a source of codes.
A36: HOW TO READ THE FLAGS
A37: BLOCKING | C37: A real defect. Do not build against this row until it is resolved.
A38: OPEN | C38: A decision is needed but the row is usable with the decision recorded.
A39: none | C39: Clean. UCUM maps, LOINC property agrees with the unit, region assigned.
A40: UNVERIFIED | C40: A code nobody has signed off yet. Not the same as a code that is wrong, and not the same as one that is right.

Sheet Anchor_Core_Set
A1: biomarker_id | B1: name_de | C1: loinc_code | D1: loinc_name | E1: loinc_status | F1: loinc_review_record | G1: unit_source | H1: unit_ucum | I1: ucum_note | J1: organ_mapping_source | K1: region_ids | L1: region_assignment | M1: tier | N1: core_set_rule | O1: source_panel | P1: providers | Q1: provider_count | R1: c3_guideline | S1: c3_guideline_url | T1: blocking_flags | U1: interval_count | V1: interval_availability
A2: BM-001 | B2: 17-Beta-Östradiol | C2: 14715-7 | D2: Estradiol (E2) [Moles/volume] in Serum or Plasma | E2: validated | F2: UNVERIFIED | G2: pmol/l | H2: pmol/L | J2: Reproductive, Endocrine | K2: gonads | L2: ok | M2: core_tier1 | N2: C1 | P2: IMD, Limbach, Meinlabor | Q2: 3 | T2: none | U2: =COUNTIF(Reference_Intervals!$B$2:$B$99,$A2) -> 2 | V2: =IF(U2>0,"interval_on_file","no_interval_abstain") -> interval_on_file
A3: BM-014 | B3: Anti-Müller-Hormon (AMH) | C3: 83104-0 | D3: Mullerian inhibiting substance [Mass/volume] in Serum or Plasma by Immunoassay | E3: validated | F3: UNVERIFIED | G3: ng/ml | H3: ng/mL | J3: Reproductive, Endocrine | K3: gonads | L3: ok | M3: core_tier2 | N3: C1prime | P3: Limbach, Meinlabor | Q3: 2 | R3: NICE NG257 Fertility problems (2026): use AMH measurement as predictor of ovarian response in assisted conception | S3: https://www.nice.org.uk/guidance/ng257 | T3: none | U3: =COUNTIF(Reference_Intervals!$B$2:$B$99,$A3) -> 0 | V3: =IF(U3>0,"interval_on_file","no_interval_abstain") -> no_interval_abstain
A4: BM-057 | B4: Biotin (Vitamin B7) | C4: 1980-2 | D4: Biotin [Mass/volume] in Serum or Plasma | E4: validated | F4: UNVERIFIED | G4: ng/l | H4: ng/L | J4: Nutritional, Systemic | K4: micronutrient_status | L4: ok | M4: core_tier2 | N4: C1prime | P4: IMD, Limbach | Q4: 2 | R4: ESPEN micronutrient guideline Rec 19.2 (via AWMF 073-019 deferral): biotin status by direct blood/urine biotin + biotinidase | S4: https://doi.org/10.1016/j.clnu.2024.01.030 | T4: none | U4: =COUNTIF(Reference_Intervals!$B$2:$B$99,$A4) -> 0 | V4: =IF(U4>0,"interval_on_file","no_interval_abstain") -> no_interval_abstain
A5: BM-060 | B5: Bor | C5: 52914-9 | D5: Boron [Moles/volume] in Serum or Plasma | E5: validated | F5: UNVERIFIED | G5: µg/l | H5: ug/L | I5: Micro sign must be ASCII u in the case sensitive form. | J5: Micronutrient, Systemic | K5: micronutrient_status | L5: ok | M5: core_tier1 | N5: C1 | P5: IMD, Limbach, Meinlabor | Q5: 3 | T5: BLOCKING: LOINC property is molar, unit is mass | U5: =COUNTIF(Reference_Intervals!$B$2:$B$99,$A5) -> 1 | V5: =IF(U5>0,"interval_on_file","no_interval_abstain") -> interval_on_file
A6: BM-063 | B6: Calcium | C6: 2000-8 | D6: Calcium [Moles/volume] in Serum or Plasma | E6: validated | F6: UNVERIFIED | G6: mmol/l | H6: mmol/L | J6: Bone, Mineral Metabolism | K6: bone|electrolyte_balance | L6: ok | M6: core_tier1 | N6: C1 | P6: IMD, Limbach, Meinlabor | Q6: 3 | T6: none | U6: =COUNTIF(Reference_Intervals!$B$2:$B$99,$A6) -> 1 | V6: =IF(U6>0,"interval_on_file","no_interval_abstain") -> interval_on_file
A7: BM-064 | B7: Calprotectin | C7: 38445-3 | D7: Calprotectin [Mass/mass] in Stool | E7: validated | F7: UNVERIFIED | G7: µg/g | H7: ug/g | I7: Micro sign must be ASCII u in the case sensitive form. | J7: Gastrointestinal | K7: gut | L7: ok | M7: core_tier2 | N7: C1prime | P7: IMD, Meinlabor | Q7: 2 | R7: NICE DG11 Faecal calprotectin diagnostic tests for inflammatory diseases of the bowel | S7: https://www.nice.org.uk/guidance/dg11 | T7: none | U7: =COUNTIF(Reference_Intervals!$B$2:$B$99,$A7) -> 1 | V7: =IF(U7>0,"interval_on_file","no_interval_abstain") -> interval_on_file
A8: BM-072 | B8: Cholesterin (gesamt) | C8: 2093-3 | D8: Cholesterol [Mass/volume] in Serum or Plasma | E8: validated | F8: UNVERIFIED | G8: mg/dl | H8: mg/dL | J8: Cardiometabolic, Hepatic | K8: lipid_transport|vasculature|liver | L8: ok | M8: core_tier1 | N8: C1 | P8: IMD, Limbach, Meinlabor | Q8: 3 | T8: none | U8: =COUNTIF(Reference_Intervals!$B$2:$B$99,$A8) -> 1 | V8: =IF(U8>0,"interval_on_file","no_interval_abstain") -> interval_on_file
A9: BM-077 | B9: Cortisol | C9: 2143-6 | D9: Cortisol [Mass/volume] in Serum or Plasma | E9: validated | F9: UNVERIFIED | G9: ng/ml | H9: ng/mL | J9: Adrenal, Endocrine | K9: adrenal | L9: ok | M9: core_tier1 | N9: C1 | P9: IMD, Limbach, Meinlabor | Q9: 3 | T9: none | U9: =COUNTIF(Reference_Intervals!$B$2:$B$99,$A9) -> 2 | V9: =IF(U9>0,"interval_on_file","no_interval_abstain") -> interval_on_file
A10: BM-078 | B10: Creatinkinase (CK) | C10: 2157-6 | D10: Creatine kinase [Enzymatic activity/volume] in Serum or Plasma | E10: validated | F10: UNVERIFIED | G10: U/l | H10: U/L | J10: Musculoskeletal | K10: skeletal_muscle | L10: ok | M10: core_tier2 | N10: C1prime | P10: Limbach, Meinlabor | Q10: 2 | R10: NICE NG238 CVD risk / lipid modification: measure creatine kinase before/on statin if unexplained muscle symptoms | S10: https://www.nice.org.uk/guidance/ng238 | T10: none | U10: =COUNTIF(Reference_Intervals!$B$2:$B$99,$A10) -> 0 | V10: =IF(U10>0,"interval_on_file","no_interval_abstain") -> no_interval_abstain
A11: BM-079 | B11: CRP (hochsensitiv) | C11: 30522-7 | D11: C reactive protein [Mass/volume] in Serum or Plasma by High sensitivity method | E11: validated | F11: UNVERIFIED | G11: mg/l | H11: mg/L | J11: Systemic Inflammation | K11: systemic_inflammation | L11: ok | M11: core_tier1 | N11: C1 | P11: IMD, Limbach, Meinlabor | Q11: 3 | T11: none | U11: =COUNTIF(Reference_Intervals!$B$2:$B$99,$A11) -> 1 | V11: =IF(U11>0,"interval_on_file","no_interval_abstain") -> interval_on_file
A12: BM-087 | B12: DHEA-S | C12: 2191-5 | D12: Dehydroepiandrosterone sulfate [Mass/volume] in Serum or Plasma | E12: validated | F12: UNVERIFIED | G12: ng/ml | H12: ng/mL | J12: Adrenal | K12: adrenal | L12: ok | M12: core_tier1 | N12: C1 | P12: IMD, Limbach, Meinlabor | Q12: 3 | T12: none | U12: =COUNTIF(Reference_Intervals!$B$2:$B$99,$A12) -> 3 | V12: =IF(U12>0,"interval_on_file","no_interval_abstain") -> interval_on_file
A13: BM-107 | B13: Ferritin | C13: 2276-4 | D13: Ferritin [Mass/volume] in Serum or Plasma | E13: validated | F13: UNVERIFIED | G13: ng/ml | H13: ng/mL | J13: Hematologic, Nutritional | K13: bone_marrow_blood|micronutrient_status | L13: ok | M13: core_tier1 | N13: C1 | P13: IMD, Limbach, Meinlabor | Q13: 3 | T13: none | U13: =COUNTIF(Reference_Intervals!$B$2:$B$99,$A13) -> 2 | V13: =IF(U13>0,"interval_on_file","no_interval_abstain") -> interval_on_file
A14: BM-111 | B14: Folsäure (Vitamin B9) | C14: 2284-8 | D14: Folate [Mass/volume] in Serum or Plasma | E14: validated | F14: UNVERIFIED | G14: ng/ml | H14: ng/mL | J14: Nutritional, Systemic | K14: micronutrient_status | L14: ok | M14: core_tier1 | N14: C1 | P14: IMD, Limbach, Meinlabor | Q14: 3 | T14: none | U14: =COUNTIF(Reference_Intervals!$B$2:$B$99,$A14) -> 1 | V14: =IF(U14>0,"interval_on_file","no_interval_abstain") -> interval_on_file
A15: BM-114 | B15: freies T3 (FT3) | C15: 3051-0 | D15: Triiodothyronine (T3) Free [Mass/volume] in Serum or Plasma | E15: validated | F15: UNVERIFIED | G15: pg/ml | H15: pg/mL | J15: Thyroid | K15: thyroid | L15: ok | M15: core_tier1 | N15: C1 | P15: IMD, Limbach, Meinlabor | Q15: 3 | T15: none | U15: =COUNTIF(Reference_Intervals!$B$2:$B$99,$A15) -> 1 | V15: =IF(U15>0,"interval_on_file","no_interval_abstain") -> interval_on_file
A16: BM-115 | B16: freies T4 (FT4) | C16: 3024-7 | D16: Thyroxine (T4) free [Mass/volume] in Serum or Plasma | E16: validated | F16: UNVERIFIED | G16: pg/ml | H16: pg/mL | J16: Thyroid | K16: thyroid | L16: ok | M16: core_tier1 | N16: C1 | P16: IMD, Limbach, Meinlabor | Q16: 3 | T16: none | U16: =COUNTIF(Reference_Intervals!$B$2:$B$99,$A16) -> 1 | V16: =IF(U16>0,"interval_on_file","no_interval_abstain") -> interval_on_file
A17: BM-119 | B17: FSH | C17: 15067-2 | D17: Follitropin [Units/volume] in Serum or Plasma | E17: validated | F17: UNVERIFIED | G17: U/l | H17: U/L | J17: Pituitary, Reproductive | K17: pituitary|gonads | L17: ok | M17: core_tier2 | N17: C1prime | P17: IMD, Meinlabor | Q17: 2 | R17: NICE NG257: offer blood test to measure serum gonadotrophins (FSH and LH) in irregular cycles | S17: https://www.nice.org.uk/guidance/ng257 | T17: none | U17: =COUNTIF(Reference_Intervals!$B$2:$B$99,$A17) -> 2 | V17: =IF(U17>0,"interval_on_file","no_interval_abstain") -> interval_on_file
A18: BM-123 | B18: Gamma-GT (GGT) | C18: 2324-2 | D18: Gamma glutamyl transferase [Enzymatic activity/volume] in Serum or Plasma | E18: validated | F18: UNVERIFIED | G18: U/l | H18: U/L | J18: Hepatobiliary | K18: liver|biliary | L18: ok | M18: core_tier1 | N18: C1 | P18: IMD, Limbach, Meinlabor | Q18: 3 | T18: none | U18: =COUNTIF(Reference_Intervals!$B$2:$B$99,$A18) -> 2 | V18: =IF(U18>0,"interval_on_file","no_interval_abstain") -> interval_on_file
A19: BM-125 | B19: Gesamteiweiß | C19: 2885-2 | D19: Protein [Mass/volume] in Serum or Plasma | E19: validated | F19: UNVERIFIED | G19: g/l | H19: g/L | J19: Systemic | K19: liver | L19: override_applied | M19: core_tier2 | N19: C1prime | P19: IMD, Limbach | Q19: 2 | R19: AWMF 021-021 S2k Zöliakie: screen for Eiweiß (Hypoproteinämie) among deficiency parameters | S19: https://register.awmf.org/de/leitlinien/detail/021-021 | T19: NOTE: region assigned by override, confirm | U19: =COUNTIF(Reference_Intervals!$B$2:$B$99,$A19) -> 2 | V19: =IF(U19>0,"interval_on_file","no_interval_abstain") -> interval_on_file
A20: BM-128 | B20: Glukose | C20: 1558-6 | D20: Fasting glucose [Mass/volume] in Serum or Plasma | E20: validated | F20: UNVERIFIED | G20: mg/dl | H20: mg/dL | J20: Metabolic | K20: metabolic_glycemic | L20: override_applied | M20: core_tier1 | N20: C1 | P20: IMD, Limbach, Meinlabor | Q20: 3 | T20: NOTE: region assigned by override, confirm | U20: =COUNTIF(Reference_Intervals!$B$2:$B$99,$A20) -> 1 | V20: =IF(U20>0,"interval_on_file","no_interval_abstain") -> interval_on_file
A21: BM-130 | B21: GOT (ASAT) | C21: 1920-8 | D21: Aspartate aminotransferase [Enzymatic activity/volume] in Serum or Plasma | E21: validated | F21: UNVERIFIED | G21: U/l | H21: U/L | J21: Hepatic, Musculoskeletal | K21: liver|skeletal_muscle | L21: ok | M21: core_tier1 | N21: C1 | P21: IMD, Limbach, Meinlabor | Q21: 3 | T21: none | U21: =COUNTIF(Reference_Intervals!$B$2:$B$99,$A21) -> 0 | V21: =IF(U21>0,"interval_on_file","no_interval_abstain") -> no_interval_abstain
A22: BM-132 | B22: GPT (ALAT) | C22: 1742-6 | D22: Alanine aminotransferase [Enzymatic activity/volume] in Serum or Plasma | E22: validated | F22: UNVERIFIED | G22: U/l | H22: U/L | J22: Hepatic | K22: liver | L22: ok | M22: core_tier1 | N22: C1 | P22: IMD, Limbach, Meinlabor | Q22: 3 | T22: none | U22: =COUNTIF(Reference_Intervals!$B$2:$B$99,$A22) -> 2 | V22: =IF(U22>0,"interval_on_file","no_interval_abstain") -> interval_on_file
A23: BM-136 | B23: Harnsäure | C23: 3084-1 | D23: Urate [Mass/volume] in Serum or Plasma | E23: validated | F23: UNVERIFIED | G23: mg/dl | H23: mg/dL | J23: Renal, Metabolic | K23: kidney | L23: NEEDS_DECISION | M23: core_tier2 | N23: C1prime | P23: Limbach, Meinlabor | Q23: 2 | R23: NICE NG219 Gout: measure serum urate to confirm diagnosis and for ULT monitoring | S23: https://www.nice.org.uk/guidance/ng219 | T23: OPEN: region assignment needs a decision | U23: =COUNTIF(Reference_Intervals!$B$2:$B$99,$A23) -> 2 | V23: =IF(U23>0,"interval_on_file","no_interval_abstain") -> interval_on_file
A24: BM-139 | B24: HbA1c | C24: 4548-4 | D24: Hemoglobin A1c/Hemoglobin.total in Blood | E24: validated | F24: UNVERIFIED | G24: % | H24: % | I24: Valid only because the LOINC term is itself a ratio. | J24: Metabolic, Pancreatic | K24: metabolic_glycemic | L24: override_applied | M24: core_tier1 | N24: C1 | P24: IMD, Limbach, Meinlabor | Q24: 3 | T24: NOTE: region assigned by override, confirm | U24: =COUNTIF(Reference_Intervals!$B$2:$B$99,$A24) -> 1 | V24: =IF(U24>0,"interval_on_file","no_interval_abstain") -> interval_on_file
A25: BM-140 | B25: HDL-Cholesterin | C25: 2085-9 | D25: Cholesterol in HDL [Mass/volume] in Serum or Plasma | E25: validated | F25: UNVERIFIED | G25: mg/dl | H25: mg/dL | J25: Cardiometabolic, Hepatic | K25: lipid_transport|vasculature|liver | L25: ok | M25: core_tier1 | N25: C1 | P25: IMD, Limbach, Meinlabor | Q25: 3 | T25: none | U25: =COUNTIF(Reference_Intervals!$B$2:$B$99,$A25) -> 2 | V25: =IF(U25>0,"interval_on_file","no_interval_abstain") -> interval_on_file
A26: BM-154 | B26: Holotranscobalamin (aktives B12) | C26: 72160-5 | D26: Holo-transcobalamin II [Moles/volume] in Serum | E26: validated | F26: UNVERIFIED | G26: pmol/l | H26: pmol/L | J26: Hematologic, Nutritional | K26: bone_marrow_blood|micronutrient_status | L26: ok | M26: core_tier1 | N26: C1 | P26: IMD, Limbach, Meinlabor | Q26: 3 | T26: none | U26: =COUNTIF(Reference_Intervals!$B$2:$B$99,$A26) -> 0 | V26: =IF(U26>0,"interval_on_file","no_interval_abstain") -> no_interval_abstain
A27: BM-156 | B27: Homocystein | C27: 13965-9 | D27: Homocysteine [Moles/volume] in Serum or Plasma | E27: validated | F27: UNVERIFIED | G27: µmol/l | H27: umol/L | I27: Micro sign must be ASCII u in the case sensitive form. | J27: Metabolic | K27: micronutrient_status | L27: override_applied | M27: core_tier2 | N27: C1prime | P27: IMD, Limbach | Q27: 2 | R27: NICE NG239 Vitamin B12 deficiency: measure plasma homocysteine | S27: https://www.nice.org.uk/guidance/ng239 | T27: NOTE: region assigned by override, confirm | U27: =COUNTIF(Reference_Intervals!$B$2:$B$99,$A27) -> 0 | V27: =IF(U27>0,"interval_on_file","no_interval_abstain") -> no_interval_abstain
A28: BM-176 | B28: Jod | C28: 2494-3 | D28: Iodine [Mass/volume] in Serum or Plasma | E28: validated | F28: UNVERIFIED | G28: µg/l | H28: ug/L | I28: Micro sign must be ASCII u in the case sensitive form. | J28: Micronutrient, Systemic | K28: micronutrient_status | L28: ok | M28: core_tier1 | N28: C1 | P28: IMD, Limbach, Meinlabor | Q28: 3 | T28: none | U28: =COUNTIF(Reference_Intervals!$B$2:$B$99,$A28) -> 0 | V28: =IF(U28>0,"interval_on_file","no_interval_abstain") -> no_interval_abstain
A29: BM-177 | B29: Kalium | C29: 2823-3 | D29: Potassium [Moles/volume] in Serum or Plasma | E29: validated | F29: UNVERIFIED | G29: mmol/l | H29: mmol/L | J29: Renal, Electrolyte Balance | K29: kidney|electrolyte_balance | L29: ok | M29: core_tier1 | N29: C1 | P29: IMD, Limbach, Meinlabor | Q29: 3 | T29: none | U29: =COUNTIF(Reference_Intervals!$B$2:$B$99,$A29) -> 1 | V29: =IF(U29>0,"interval_on_file","no_interval_abstain") -> interval_on_file
A30: BM-186 | B30: Kupfer | C30: 14665-4 | D30: Copper [Moles/volume] in Serum or Plasma | E30: validated | F30: UNVERIFIED | G30: µg/l | H30: ug/L | I30: Micro sign must be ASCII u in the case sensitive form. | J30: Micronutrient, Systemic | K30: micronutrient_status | L30: ok | M30: core_tier1 | N30: C1 | P30: IMD, Limbach, Meinlabor | Q30: 3 | T30: BLOCKING: LOINC property is molar, unit is mass | U30: =COUNTIF(Reference_Intervals!$B$2:$B$99,$A30) -> 0 | V30: =IF(U30>0,"interval_on_file","no_interval_abstain") -> no_interval_abstain
A31: BM-190 | B31: LDL-Cholesterin | C31: 2089-1 | D31: Cholesterol in LDL [Mass/volume] in Serum or Plasma | E31: validated | F31: UNVERIFIED | G31: mg/dl | H31: mg/dL | J31: Cardiometabolic, Hepatic | K31: lipid_transport|vasculature|liver | L31: ok | M31: core_tier1 | N31: C1 | P31: IMD, Limbach, Meinlabor | Q31: 3 | T31: none | U31: =COUNTIF(Reference_Intervals!$B$2:$B$99,$A31) -> 5 | V31: =IF(U31>0,"interval_on_file","no_interval_abstain") -> interval_on_file
A32: BM-197 | B32: LH | C32: 10501-5 | D32: Lutropin [Units/volume] in Serum or Plasma | E32: validated | F32: UNVERIFIED | G32: U/l | H32: U/L | J32: Pituitary, Reproductive | K32: pituitary|gonads | L32: ok | M32: core_tier2 | N32: C1prime | P32: IMD, Meinlabor | Q32: 2 | R32: NICE NG257: offer blood test to measure serum gonadotrophins (FSH and LH) in irregular cycles | S32: https://www.nice.org.uk/guidance/ng257 | T32: none | U32: =COUNTIF(Reference_Intervals!$B$2:$B$99,$A32) -> 2 | V32: =IF(U32>0,"interval_on_file","no_interval_abstain") -> interval_on_file
A33: BM-200 | B33: Lipoprotein (a) | C33: 10835-7 | D33: Lipoprotein a [Mass/volume] in Serum or Plasma | E33: validated | F33: UNVERIFIED | G33: mg/dl | H33: mg/dL | J33: Cardiometabolic, Hepatic | K33: lipid_transport|vasculature|liver | L33: ok | M33: core_tier1 | N33: C1 | P33: IMD, Limbach, Meinlabor | Q33: 3 | T33: none | U33: =COUNTIF(Reference_Intervals!$B$2:$B$99,$A33) -> 0 | V33: =IF(U33>0,"interval_on_file","no_interval_abstain") -> no_interval_abstain
A34: BM-258 | B34: Magnesium | C34: 2601-3 | D34: Magnesium [Moles/volume] in Serum or Plasma | E34: validated | F34: UNVERIFIED | G34: mmol/l | H34: mmol/L | J34: Metabolic, Neuromuscular | K34: electrolyte_balance | L34: override_applied | M34: core_tier1 | N34: C1 | P34: IMD, Limbach, Meinlabor | Q34: 3 | T34: NOTE: region assigned by override, confirm | U34: =COUNTIF(Reference_Intervals!$B$2:$B$99,$A34) -> 1 | V34: =IF(U34>0,"interval_on_file","no_interval_abstain") -> interval_on_file
A35: BM-286 | B35: Natrium | C35: 2951-2 | D35: Sodium [Moles/volume] in Serum or Plasma | E35: validated | F35: UNVERIFIED | G35: mmol/l | H35: mmol/L | J35: Renal, Electrolyte Balance | K35: kidney|electrolyte_balance | L35: ok | M35: core_tier1 | N35: C1 | P35: IMD, Limbach, Meinlabor | Q35: 3 | T35: none | U35: =COUNTIF(Reference_Intervals!$B$2:$B$99,$A35) -> 1 | V35: =IF(U35>0,"interval_on_file","no_interval_abstain") -> interval_on_file
A36: BM-299 | B36: Parathormon (PTH) | C36: 2731-8 | D36: Parathyrin.intact [Mass/volume] in Serum or Plasma | E36: validated | F36: UNVERIFIED | G36: pg/ml | H36: pg/mL | J36: Parathyroid, Bone | K36: parathyroid|bone | L36: ok | M36: core_tier1 | N36: C1 | P36: IMD, Limbach, Meinlabor | Q36: 3 | T36: none | U36: =COUNTIF(Reference_Intervals!$B$2:$B$99,$A36) -> 0 | V36: =IF(U36>0,"interval_on_file","no_interval_abstain") -> no_interval_abstain
A37: BM-311 | B37: Progesteron | C37: 14890-8 | D37: Progesterone [Moles/volume] in Serum or Plasma | E37: validated | F37: UNVERIFIED | G37: nmol/l | H37: nmol/L | J37: Reproductive, Endocrine | K37: gonads | L37: ok | M37: core_tier1 | N37: C1 | P37: IMD, Limbach, Meinlabor | Q37: 3 | T37: none | U37: =COUNTIF(Reference_Intervals!$B$2:$B$99,$A37) -> 1 | V37: =IF(U37>0,"interval_on_file","no_interval_abstain") -> interval_on_file
A38: BM-312 | B38: Prolaktin | C38: 2842-3 | D38: Prolactin [Mass/volume] in Serum or Plasma | E38: validated | F38: UNVERIFIED | G38: µg/l | H38: ug/L | I38: Micro sign must be ASCII u in the case sensitive form. | J38: Pituitary, Reproductive | K38: pituitary|gonads | L38: ok | M38: core_tier2 | N38: C1prime | P38: IMD, Meinlabor | Q38: 2 | R38: NICE NG257: measure prolactin when ovulatory disorder, galactorrhoea, or suspected pituitary tumour | S38: https://www.nice.org.uk/guidance/ng257 | T38: none | U38: =COUNTIF(Reference_Intervals!$B$2:$B$99,$A38) -> 2 | V38: =IF(U38>0,"interval_on_file","no_interval_abstain") -> interval_on_file
A39: BM-315 | B39: PSA | C39: 2857-1 | D39: Prostate specific Ag [Mass/volume] in Serum or Plasma | E39: validated | F39: UNVERIFIED | G39: ng/ml | H39: ng/mL | J39: Prostate | K39: prostate | L39: ok | M39: core_tier2 | N39: C1prime | P39: Limbach, Meinlabor | Q39: 2 | R39: NICE NG131 Prostate cancer: measure PSA for diagnosis pathway, active surveillance, and follow-up | S39: https://www.nice.org.uk/guidance/ng131 | T39: none | U39: =COUNTIF(Reference_Intervals!$B$2:$B$99,$A39) -> 0 | V39: =IF(U39>0,"interval_on_file","no_interval_abstain") -> no_interval_abstain
A40: BM-341 | B40: Selen | C40: 5724-0 | D40: Selenium [Mass/volume] in Serum or Plasma | E40: validated | F40: UNVERIFIED | G40: µg/l | H40: ug/L | I40: Micro sign must be ASCII u in the case sensitive form. | J40: Micronutrient, Systemic | K40: micronutrient_status | L40: ok | M40: core_tier1 | N40: C1 | P40: IMD, Limbach, Meinlabor | Q40: 3 | T40: none | U40: =COUNTIF(Reference_Intervals!$B$2:$B$99,$A40) -> 0 | V40: =IF(U40>0,"interval_on_file","no_interval_abstain") -> no_interval_abstain
...

Sheet Region_Enum
A1: region_id | B1: region_kind | C1: label | D1: snomed_body_structure | E1: uberon_id | F1: snomed_review_record | G1: uberon_review_record | H1: markers_mapped
A2: liver | B2: anatomical | C2: Liver | D2: 10200004 | E2: UBERON:0002107 | F2: UNVERIFIED | G2: UNVERIFIED | H2: =SUMPRODUCT(--ISNUMBER(SEARCH("|"&$A2&"|","|"&Anchor_Core_Set!$K$2:$K$68&"|"))) -> 10
A3: biliary | B3: anatomical | C3: Biliary tract | D3: 28273000 | E3: UBERON:0002394 | F3: UNVERIFIED | G3: UNVERIFIED | H3: =SUMPRODUCT(--ISNUMBER(SEARCH("|"&$A3&"|","|"&Anchor_Core_Set!$K$2:$K$68&"|"))) -> 1
A4: kidney | B4: anatomical | C4: Kidney | D4: 64033007 | E4: UBERON:0002113 | F4: UNVERIFIED | G4: UNVERIFIED | H4: =SUMPRODUCT(--ISNUMBER(SEARCH("|"&$A4&"|","|"&Anchor_Core_Set!$K$2:$K$68&"|"))) -> 4
A5: thyroid | B5: anatomical | C5: Thyroid gland | D5: 69748006 | E5: UBERON:0002046 | F5: UNVERIFIED | G5: UNVERIFIED | H5: =SUMPRODUCT(--ISNUMBER(SEARCH("|"&$A5&"|","|"&Anchor_Core_Set!$K$2:$K$68&"|"))) -> 3
A6: parathyroid | B6: anatomical | C6: Parathyroid gland | D6: 111002 | E6: UBERON:0001132 | F6: UNVERIFIED | G6: UNVERIFIED | H6: =SUMPRODUCT(--ISNUMBER(SEARCH("|"&$A6&"|","|"&Anchor_Core_Set!$K$2:$K$68&"|"))) -> 1
A7: pituitary | B7: anatomical | C7: Pituitary gland | D7: 56329008 | E7: UBERON:0000007 | F7: UNVERIFIED | G7: UNVERIFIED | H7: =SUMPRODUCT(--ISNUMBER(SEARCH("|"&$A7&"|","|"&Anchor_Core_Set!$K$2:$K$68&"|"))) -> 4
A8: adrenal | B8: anatomical | C8: Adrenal gland | D8: 23451007 | E8: UBERON:0002369 | F8: UNVERIFIED | G8: UNVERIFIED | H8: =SUMPRODUCT(--ISNUMBER(SEARCH("|"&$A8&"|","|"&Anchor_Core_Set!$K$2:$K$68&"|"))) -> 2
A9: pancreas_endocrine | B9: anatomical | C9: Pancreas, endocrine | D9: 15776009 | E9: UBERON:0000016 | F9: UNVERIFIED | G9: UNVERIFIED | H9: =SUMPRODUCT(--ISNUMBER(SEARCH("|"&$A9&"|","|"&Anchor_Core_Set!$K$2:$K$68&"|"))) -> 0
A10: gut | B10: anatomical | C10: Intestinal tract | D10: 113276009 | E10: UBERON:0000160 | F10: UNVERIFIED | G10: UNVERIFIED | H10: =SUMPRODUCT(--ISNUMBER(SEARCH("|"&$A10&"|","|"&Anchor_Core_Set!$K$2:$K$68&"|"))) -> 1
A11: prostate | B11: anatomical | C11: Prostate | D11: 41216001 | E11: UBERON:0002367 | F11: UNVERIFIED | G11: UNVERIFIED | H11: =SUMPRODUCT(--ISNUMBER(SEARCH("|"&$A11&"|","|"&Anchor_Core_Set!$K$2:$K$68&"|"))) -> 1
A12: gonads | B12: anatomical | C12: Gonads | D12: 18620006 | E12: UBERON:0000991 | F12: UNVERIFIED | G12: UNVERIFIED | H12: =SUMPRODUCT(--ISNUMBER(SEARCH("|"&$A12&"|","|"&Anchor_Core_Set!$K$2:$K$68&"|"))) -> 7
A13: bone | B13: anatomical | C13: Bone | D13: 272673000 | E13: UBERON:0001474 | F13: UNVERIFIED | G13: UNVERIFIED | H13: =SUMPRODUCT(--ISNUMBER(SEARCH("|"&$A13&"|","|"&Anchor_Core_Set!$K$2:$K$68&"|"))) -> 5
... A18: brain | B18: anatomical | C18: Brain | D18: 12738006 | E18: UBERON:0000955 | F18: UNVERIFIED | G18: UNVERIFIED | H18: =SUMPRODUCT(--ISNUMBER(SEARCH("|"&$A18&"|","|"&Anchor_Core_Set!$K$2:$K$68&"|"))) -> 0
A19: systemic_inflammation | B19: system | C19: Systemic inflammation | F19: n/a (system region) | G19: n/a (system region) | H19: =SUMPRODUCT(--ISNUMBER(SEARCH("|"&$A19&"|","|"&Anchor_Core_Set!$K$2:$K$68&"|"))) -> 1
A20: immune | B20: system | C20: Immune function | F20: n/a (system region) | G20: n/a (system region) | H20: =SUMPRODUCT(--ISNUMBER(SEARCH("|"&$A20&"|","|"&Anchor_Core_Set!$K$2:$K$68&"|"))) -> 4
A21: micronutrient_status | B21: system | C21: Micronutrient status | F21: n/a (system region) | G21: n/a (system region) | H21: =SUMPRODUCT(--ISNUMBER(SEARCH("|"&$A21&"|","|"&Anchor_Core_Set!$K$2:$K$68&"|"))) -> 18
A22: electrolyte_balance | B22: system | C22: Electrolyte and water balance | F22: n/a (system region) | G22: n/a (system region) | H22: =SUMPRODUCT(--ISNUMBER(SEARCH("|"&$A22&"|","|"&Anchor_Core_Set!$K$2:$K$68&"|"))) -> 4
A23: metabolic_glycemic | B23: system | C23: Glycemic regulation | F23: n/a (system region) | G23: n/a (system region) | H23: =SUMPRODUCT(--ISNUMBER(SEARCH("|"&$A23&"|","|"&Anchor_Core_Set!$K$2:$K$68&"|"))) -> 2
A24: lipid_transport | B24: system | C24: Lipid transport | F24: n/a (system region) | G24: n/a (system region) | H24: =SUMPRODUCT(--ISNUMBER(SEARCH("|"&$A24&"|","|"&Anchor_Core_Set!$K$2:$K$68&"|"))) -> 5
A25: body_composition | B25: system | C25: Body composition | F25: n/a (system region) | G25: n/a (system region) | H25: =SUMPRODUCT(--ISNUMBER(SEARCH("|"&$A25&"|","|"&Anchor_Core_Set!$K$2:$K$68&"|"))) -> 0
A26: sleep_recovery | B26: system | C26: Sleep and autonomic recovery | F26: n/a (system region) | G26: n/a (system region) | H26: =SUMPRODUCT(--ISNUMBER(SEARCH("|"&$A26&"|","|"&Anchor_Core_Set!$K$2:$K$68&"|"))) -> 0
A28: The enum is CLOSED. Adding a region is a contract change and needs an ADR, because the XR layer must have a mesh or an affordance for every value.
A29: SNOMED and UBERON codes below are PROPOSED and every one is UNVERIFIED. None may enter the repo until a named human has signed a review record. Do not treat this sheet as a source of codes.
A30: Five regions currently carry no Anchor marker: pancreas_endocrine, heart, brain, body_composition and sleep_recovery. pancreas_endocrine is empty because the core set holds no insulin or C-peptide; the others are Dynamic-layer placeholders. All five must render as "no data", never as healthy.

Sheet Organ_Mapping_Crosswalk
A1: organ_mapping_token | B1: markers_using_token | C1: proposed_region_ids | D1: verdict
A2: Adrenal | B2: 2 | C2: adrenal | D2: KEEP: one to one
A3: Bone | B3: 5 | C3: bone | D3: KEEP: one to one
A4: Cardiometabolic | B4: 5 | C4: lipid_transport|vasculature | D4: SPLIT: risk concept, maps to more than one region
A5: Electrolyte Balance | B5: 2 | C5: electrolyte_balance | D5: KEEP: one to one
A6: Endocrine | B6: 7 | D6: RETIRE: carries no locational information
A7: Gastrointestinal | B7: 1 | C7: gut | D7: KEEP: one to one
A8: Hematologic | B8: 10 | C8: bone_marrow_blood | D8: KEEP: one to one
A9: Hepatic | B9: 8 | C9: liver | D9: KEEP: one to one
A10: Hepatobiliary | B10: 1 | C10: liver|biliary | D10: SPLIT: risk concept, maps to more than one region
A11: Immune | B11: 4 | C11: immune | D11: KEEP: one to one
A12: Metabolic | B12: 5 | D12: RETIRE: names a pathway, not a location. Resolved per marker.
A13: Micronutrient | B13: 5 | C13: micronutrient_status | D13: KEEP: one to one
A14: Mineral Metabolism | B14: 1 | C14: bone|electrolyte_balance | D14: SPLIT: risk concept, maps to more than one region
A15: Musculoskeletal | B15: 2 | C15: skeletal_muscle | D15: KEEP: one to one
A16: Neuromuscular | B16: 1 | C16: skeletal_muscle | D16: KEEP: one to one
A17: Nutritional | B17: 12 | C17: micronutrient_status | D17: KEEP: one to one
A18: Pancreatic | B18: 1 | C18: pancreas_endocrine | D18: KEEP: one to one
A19: Parathyroid | B19: 1 | C19: parathyroid | D19: KEEP: one to one
A20: Pituitary | B20: 4 | C20: pituitary | D20: KEEP: one to one
A21: Prostate | B21: 1 | C21: prostate | D21: KEEP: one to one
A22: Renal | B22: 4 | C22: kidney | D22: KEEP: one to one
A23: Reproductive | B23: 7 | C23: gonads | D23: KEEP: one to one
A24: Systemic | B24: 17 | D24: RETIRE: carries no locational information
A25: Systemic Inflammation | B25: 1 | C25: systemic_inflammation | D25: KEEP: one to one
A26: Thyroid | B26: 3 | C26: thyroid | D26: KEEP: one to one
A27: Thyroid Axis | B27: 1 | C27: thyroid|pituitary | D27: SPLIT: risk concept, maps to more than one region

Sheet Reference_Intervals
A1: interval_id | B1: biomarker_id | C1: name_de | D1: in_core_set | E1: record_kind | F1: population | G1: low | H1: high | I1: unit | J1: unit_ucum | K1: reference_range_text | L1: issuer | M1: issuer_kind | N1: assay_or_catalogue | O1: source_url | P1: retrieved_at | Q1: source | R1: parse_status
A2: RI-001 | B2: BM-001 | C2: 17-Beta-Östradiol | D2: 1 | E2: reference_interval | F2: male | G2: 40 | H2: 161 | I2: pmol/l | J2: pmol/L | K2: m 40-161 · w Follikelphase 77-921 · Zyklusmitte 139-2382 · Lutealphase 77-1145 · Postmenopause < 103 | L2: IMD Labor Berlin-Potsdam | M2: LAB | N2: Referenzbereiche Standort Potsdam, Stand 28.09.2015 | O2: https://www.imd-berlin.de/fileadmin/user_upload/leistungsverzeichnis_druck/09a_Referenzbereiche_Standort_Potsdam.pdf | P2: 2026-07-12 | Q2: IMD-POT-2015 | R2: structured
A3: RI-002 | B3: BM-001 | C3: 17-Beta-Östradiol | D3: 1 | E3: reference_interval | F3: female_Follikelphase | G3: 77 | H3: 921 | I3: pmol/l | J3: pmol/L | K3: m 40-161 · w Follikelphase 77-921 · Zyklusmitte 139-2382 · Lutealphase 77-1145 · Postmenopause < 103 | L3: IMD Labor Berlin-Potsdam | M3: LAB | N3: Referenzbereiche Standort Potsdam, Stand 28.09.2015 | O3: https://www.imd-berlin.de/fileadmin/user_upload/leistungsverzeichnis_druck/09a_Referenzbereiche_Standort_Potsdam.pdf | P3: 2026-07-12 | Q3: IMD-POT-2015 | R3: structured
A4: RI-003 | B4: BM-002 | C4: 8-OHdG Urin | D4: 0 | E4: reference_interval | F4: general_adult | G4: 0.1 | H4: 2.4 | I4: µmol/mol Krea | J4: umol/mol | K4: 0,1-2,4 | L4: IMD Berlin | M4: LAB | N4: Leistungsverzeichnis, Stand 12.02.2025 | O4: https://www.imd-berlin.de/fileadmin/user_upload/leistungsverzeichnis_druck/imd_leistungsverzeichnis_2025-03-06.pdf | P4: 2026-07-12 | Q4: IMD-LV-2025 | R4: structured
A5: RI-004 | B5: BM-004 | C5: ADMA | D5: 0 | E5: reference_interval | F5: general_adult | G5: 50 | H5: 110 | I5: µg/l | J5: ug/L | K5: 50-110 | L5: IMD Berlin | M5: LAB | N5: Leistungsverzeichnis, Stand 12.02.2025 | O5: https://www.imd-berlin.de/fileadmin/user_upload/leistungsverzeichnis_druck/imd_leistungsverzeichnis_2025-03-06.pdf | P5: 2026-07-12 | Q5: IMD-LV-2025 | R5: structured
A6: RI-005 | B6: BM-005 | C6: AGE | D6: 0 | E6: reference_interval | F6: general_adult | H6: 67 | I6: µg/ml | J6: ug/mL | K6: < 67 | L6: IMD Berlin | M6: LAB | N6: Leistungsverzeichnis, Stand 12.02.2025 | O6: https://www.imd-berlin.de/fileadmin/user_upload/leistungsverzeichnis_druck/imd_leistungsverzeichnis_2025-03-06.pdf | P6: 2026-07-12 | Q6: IMD-LV-2025 | R6: structured
A7: RI-006 | B7: BM-007 | C7: Alkalische Phosphatase (AP) | D7: 0 | E7: reference_interval | F7: age_>20J | G7: 40 | H7: 150 | I7: U/l | J7: U/L | K7: > 20 J: 40-150 (m und w) | L7: IMD Berlin | M7: LAB | N7: Leistungsverzeichnis, Stand 12.02.2025 | O7: https://www.imd-berlin.de/fileadmin/user_upload/leistungsverzeichnis_druck/imd_leistungsverzeichnis_2025-03-06.pdf | P7: 2026-07-12 | Q7: IMD-LV-2025 | R7: structured
A8: RI-007 | B8: BM-012 | C8: Androstendion | D8: 0 | E8: reference_interval | F8: age_>21J_female_vor Menopause | G8: 0.4 | H8: 3.4 | I8: ng/ml | J8: ng/mL | K8: > 21 J: w vor Menopause 0,40-3,40 · w nach Menopause < 2,11 · m 0,50-3,50 | L8: IMD Berlin | M8: LAB | N8: Leistungsverzeichnis, Stand 12.02.2025 | O8: https://www.imd-berlin.de/fileadmin/user_upload/leistungsverzeichnis_druck/imd_leistungsverzeichnis_2025-03-06.pdf | P8: 2026-07-12 | Q8: IMD-LV-2025 | R8: structured
A9: RI-008 | B9: BM-012 | C9: Androstendion | D9: 0 | E9: reference_interval | F9: female_nach Menopause | H9: 2.11 | I9: ng/ml | J9: ng/mL | K9: > 21 J: w vor Menopause 0,40-3,40 · w nach Menopause < 2,11 · m 0,50-3,50 | L9: IMD Berlin | M9: LAB | N9: Leistungsverzeichnis, Stand 12.02.2025 | O9: https://www.imd-berlin.de/fileadmin/user_upload/leistungsverzeichnis_druck/imd_leistungsverzeichnis_2025-03-06.pdf | P9: 2026-07-12 | Q9: IMD-LV-2025 | R9: structured
A10: RI-009 | B10: BM-012 | C10: Androstendion | D10: 0 | E10: reference_interval | F10: male | G10: 0.5 | H10: 3.5 | I10: ng/ml | J10: ng/mL | K10: > 21 J: w vor Menopause 0,40-3,40 · w nach Menopause < 2,11 · m 0,50-3,50 | L10: IMD Berlin | M10: LAB | N10: Leistungsverzeichnis, Stand 12.02.2025 | O10: https://www.imd-berlin.de/fileadmin/user_upload/leistungsverzeichnis_druck/imd_leistungsverzeichnis_2025-03-06.pdf | P10: 2026-07-12 | Q10: IMD-LV-2025 | R10: structured
A11: RI-010 | B11: BM-018 | C11: APC-Resistenz | D11: 0 | E11: reference_interval | F11: general_adult | G11: 2.2 | I11: Ratio | J11: 1 | K11: > 2,2 | L11: IMD Berlin | M11: LAB | N11: Leistungsverzeichnis, Stand 12.02.2025 | O11: https://www.imd-berlin.de/fileadmin/user_upload/leistungsverzeichnis_druck/imd_leistungsverzeichnis_2025-03-06.pdf | P11: 2026-07-12 | Q11: IMD-LV-2025 | R11: structured
A12: RI-011 | B12: BM-019 | C12: Apolipoprotein B | D12: 0 | E12: reference_interval | F12: age_>18J | G12: 1 | I12: g/l | J12: g/L | K12: > 18 J: > 1,0 (wie im Katalog angegeben) | L12: IMD Berlin | M12: LAB | N12: Leistungsverzeichnis, Stand 12.02.2025 | O12: https://www.imd-berlin.de/fileadmin/user_upload/leistungsverzeichnis_druck/imd_leistungsverzeichnis_2025-03-06.pdf | P12: 2026-07-12 | Q12: IMD-LV-2025 | R12: structured
A13: RI-012 | B13: BM-026 | C13: ATP intrazellulär | D13: 0 | E13: reference_interval | F13: general_adult | G13: 2.5 | I13: µM | J13: umol/L | K13: > 2,5 | L13: IMD Berlin | M13: LAB | N13: Leistungsverzeichnis, Stand 12.02.2025 | O13: https://www.imd-berlin.de/fileadmin/user_upload/leistungsverzeichnis_druck/imd_leistungsverzeichnis_2025-03-06.pdf | P13: 2026-07-12 | Q13: IMD-LV-2025 | R13: structured
A14: RI-013 | B14: BM-052 | C14: BDNF (Brain-Derived Neurotrophic Factor) | D14: 0 | E14: reference_interval | F14: general_adult | G14: 18.3 | H14: 31.4 | I14: ng/ml | J14: ng/mL | K14: 18,3-31,4 | L14: IMD Berlin | M14: LAB | N14: Leistungsverzeichnis, Stand 12.02.2025 | O14: https://www.imd-berlin.de/fileadmin/user_upload/leistungsverzeichnis_druck/imd_leistungsverzeichnis_2025-03-06.pdf | P14: 2026-07-12 | Q14: IMD-LV-2025 | R14: structured
A15: RI-014 | B15: BM-055 | C15: Beta-Defensin 2 Stuhl | D15: 0 | E15: reference_interval | F15: general_adult | G15: 8 | H15: 60 | I15: ng/g | J15: ng/g | K15: 8-60 | L15: IMD Berlin | M15: LAB | N15: Leistungsverzeichnis, Stand 12.02.2025 | O15: https://www.imd-berlin.de/fileadmin/user_upload/leistungsverzeichnis_druck/imd_leistungsverzeichnis_2025-03-06.pdf | P15: 2026-07-12 | Q15: IMD-LV-2025 | R15: structured
A16: RI-015 | B16: BM-056 | C16: Bilirubin | D16: 0 | E16: reference_interval | F16: age_>18J | G16: 0.2 | H16: 1.2 | I16: mg/dl | J16: mg/dL | K16: > 18 J: 0,20-1,20 | L16: IMD Berlin | M16: LAB | N16: Leistungsverzeichnis, Stand 12.02.2025 | O16: https://www.imd-berlin.de/fileadmin/user_upload/leistungsverzeichnis_druck/imd_leistungsverzeichnis_2025-03-06.pdf | P16: 2026-07-12 | Q16: IMD-LV-2025 | R16: structured
A17: RI-016 | B17: BM-059 | C17: Blei | D17: 0 | E17: reference_interval | F17: general_adult | H17: 28 | I17: µg/l | J17: ug/L | K17: < 28 | L17: IMD Berlin | M17: LAB | N17: Leistungsverzeichnis, Stand 12.02.2025 | O17: https://www.imd-berlin.de/fileadmin/user_upload/leistungsverzeichnis_druck/imd_leistungsverzeichnis_2025-03-06.pdf | P17: 2026-07-12 | Q17: IMD-LV-2025 | R17: structured
A18: RI-017 | B18: BM-060 | C18: Bor | D18: 1 | E18: reference_interval | F18: general_adult | G18: 37.4 | H18: 101 | I18: µg/l | J18: ug/L | K18: 37,4-101 | L18: IMD Berlin | M18: LAB | N18: Leistungsverzeichnis, Stand 12.02.2025 | O18: https://www.imd-berlin.de/fileadmin/user_upload/leistungsverzeichnis_druck/imd_leistungsverzeichnis_2025-03-06.pdf | P18: 2026-07-12 | Q18: IMD-LV-2025 | R18: structured
A19: RI-018 | B19: BM-062 | C19: Cadmium | D19: 0 | E19: reference_interval | F19: general_adult | H19: 0.6 | I19: µg/l | J19: ug/L | K19: < 0,6 | L19: IMD Berlin | M19: LAB | N19: Leistungsverzeichnis, Stand 12.02.2025 | O19: https://www.imd-berlin.de/fileadmin/user_upload/leistungsverzeichnis_druck/imd_leistungsverzeichnis_2025-03-06.pdf | P19: 2026-07-12 | Q19: IMD-LV-2025 | R19: structured
A20: RI-019 | B20: BM-063 | C20: Calcium | D20: 1 | E20: reference_interval | F20: age_12-60J | G20: 2.2 | H20: 2.6 | I20: mmol/l | J20: mmol/L | K20: 12-60 J: 2,20-2,60 · m > 60 J: 2,20-2,55 | L20: IMD Berlin | M20: LAB | N20: Leistungsverzeichnis, Stand 12.02.2025 | O20: https://www.imd-berlin.de/fileadmin/user_upload/leistungsverzeichnis_druck/imd_leistungsverzeichnis_2025-03-06.pdf | P20: 2026-07-12 | Q20: IMD-LV-2025 | R20: structured
A21: RI-020 | B21: BM-064 | C21: Calprotectin | D21: 1 | E21: reference_interval | F21: general_adult | H21: 50 | I21: µg/g | J21: ug/g | K21: < 50 | L21: IMD Berlin | M21: LAB | N21: Leistungsverzeichnis, Stand 12.02.2025 | O21: https://www.imd-berlin.de/fileadmin/user_upload/leistungsverzeichnis_druck/imd_leistungsverzeichnis_2025-03-06.pdf | P21: 2026-07-12 | Q21: IMD-LV-2025 | R21: structured
A22: RI-021 | B22: BM-068 | C22: Carnitin | D22: 0 | E22: reference_interval | F22: age_>1J_female | G22: 17.9 | H22: 45.5 | I22: µmol/l | J22: umol/L | K22: > 1 J: w 17,9-45,5 · m 24,6-51,0 | L22: IMD Berlin | M22: LAB | N22: Leistungsverzeichnis, Stand 12.02.2025 | O22: https://www.imd-berlin.de/fileadmin/user_upload/leistungsverzeichnis_druck/imd_leistungsverzeichnis_2025-03-06.pdf | P22: 2026-07-12 | Q22: IMD-LV-2025 | R22: structured
A23: RI-022 | B23: BM-068 | C23: Carnitin | D23: 0 | E23: reference_interval | F23: male | G23: 24.6 | H23: 51 | I23: µmol/l | J23: umol/L | K23: > 1 J: w 17,9-45,5 · m 24,6-51,0 | L23: IMD Berlin | M23: LAB | N23: Leistungsverzeichnis, Stand 12.02.2025 | O23: https://www.imd-berlin.de/fileadmin/user_upload/leistungsverzeichnis_druck/imd_leistungsverzeichnis_2025-03-06.pdf | P23: 2026-07-12 | Q23: IMD-LV-2025 | R23: structured
A24: RI-023 | B24: BM-069 | C24: CD57+ NK-Zellen | D24: 0 | E24: reference_interval | F24: general_adult | G24: 60 | H24: 360 | I24: /µl | J24: /uL | K24: 60-360 | L24: IMD Berlin | M24: LAB | N24: Leistungsverzeichnis, Stand 12.02.2025 | O24: https://www.imd-berlin.de/fileadmin/user_upload/leistungsverzeichnis_druck/imd_leistungsverzeichnis_2025-03-06.pdf | P24: 2026-07-12 | Q24: IMD-LV-2025 | R24: structured
A25: RI-024 | B25: BM-070 | C25: CDT (Alkoholmarker) | D25: 0 | E25: reference_interval | F25: general_adult | H25: 1.75 | I25: % | J25: % | K25: < 1,75 | L25: IMD Berlin | M25: LAB | N25: Leistungsverzeichnis, Stand 12.02.2025 | O25: https://www.imd-berlin.de/fileadmin/user_upload/leistungsverzeichnis_druck/imd_leistungsverzeichnis_2025-03-06.pdf | P25: 2026-07-12 | Q25: IMD-LV-2025 | R25: structured
A26: RI-025 | B26: BM-071 | C26: Chlorid | D26: 0 | E26: reference_interval | F26: age_1mo_90J | G26: 98 | H26: 107 | I26: mmol/l | J26: mmol/L | K26: 1 Monat-90 J: 98-107 | L26: IMD Berlin | M26: LAB | N26: Leistungsverzeichnis, Stand 12.02.2025 | O26: https://www.imd-berlin.de/fileadmin/user_upload/leistungsverzeichnis_druck/imd_leistungsverzeichnis_2025-03-06.pdf | P26: 2026-07-12 | Q26: IMD-LV-2025 | R26: structured
A27: RI-026 | B27: BM-072 | C27: Cholesterin (gesamt) | D27: 1 | E27: reference_interval | F27: age_>18J | H27: 190 | I27: mg/dl | J27: mg/dL | K27: > 18 J: < 190 | L27: IMD Berlin | M27: LAB | N27: Leistungsverzeichnis, Stand 12.02.2025 | O27: https://www.imd-berlin.de/fileadmin/user_upload/leistungsverzeichnis_druck/imd_leistungsverzeichnis_2025-03-06.pdf | P27: 2026-07-12 | Q27: IMD-LV-2025 | R27: structured
A28: RI-027 | B28: BM-073 | C28: Chrom | D28: 0 | E28: reference_interval | F28: general_adult | G28: 0.14 | H28: 0.52 | I28: µg/l | J28: ug/L | K28: 0,14-0,52 | L28: IMD Berlin | M28: LAB | N28: Leistungsverzeichnis, Stand 12.02.2025 | O28: https://www.imd-berlin.de/fileadmin/user_upload/leistungsverzeichnis_druck/imd_leistungsverzeichnis_2025-03-06.pdf | P28: 2026-07-12 | Q28: IMD-LV-2025 | R28: structured
A29: RI-028 | B29: BM-076 | C29: Coenzym Q10 | D29: 0 | E29: reference_interval | F29: general_adult | G29: 0.6 | I29: mg/l | J29: mg/L | K29: > 0,60 | L29: IMD Berlin | M29: LAB | N29: Leistungsverzeichnis, Stand 12.02.2025 | O29: https://www.imd-berlin.de/fileadmin/user_upload/leistungsverzeichnis_druck/imd_leistungsverzeichnis_2025-03-06.pdf | P29: 2026-07-12 | Q29: IMD-LV-2025 | R29: structured
A30: RI-029 | B30: BM-077 | C30: Cortisol | D30: 1 | E30: reference_interval | F30: time_vor_10h | G30: 37 | H30: 194 | I30: ng/ml | J30: ng/mL | K30: vor 10 Uhr 37-194 · nach 17 Uhr 29-173 | L30: IMD Berlin | M30: LAB | N30: Leistungsverzeichnis, Stand 12.02.2025 | O30: https://www.imd-berlin.de/fileadmin/user_upload/leistungsverzeichnis_druck/imd_leistungsverzeichnis_2025-03-06.pdf | P30: 2026-07-12 | Q30: IMD-LV-2025 | R30: structured
A31: RI-030 | B31: BM-077 | C31: Cortisol | D31: 1 | E31: reference_interval | F31: time_nach_17h | G31: 29 | H31: 173 | I31: ng/ml | J31: ng/mL | K31: vor 10 Uhr 37-194 · nach 17 Uhr 29-173 | L31: IMD Berlin | M31: LAB | N31: Leistungsverzeichnis, Stand 12.02.2025 | O31: https://www.imd-berlin.de/fileadmin/user_upload/leistungsverzeichnis_druck/imd_leistungsverzeichnis_2025-03-06.pdf | P31: 2026-07-12 | Q31: IMD-LV-2025 | R31: structured
A32: RI-031 | B32: BM-079 | C32: CRP (hochsensitiv) | D32: 1 | E32: reference_interval | F32: general_adult | H32: 5 | I32: mg/l | J32: mg/L | K32: < 5 | L32: IMD Berlin | M32: LAB | N32: Leistungsverzeichnis, Stand 12.02.2025 | O32: https://www.imd-berlin.de/fileadmin/user_upload/leistungsverzeichnis_druck/imd_leistungsverzeichnis_2025-03-06.pdf | P32: 2026-07-12 | Q32: IMD-LV-2025 | R32: structured
A33: RI-032 | B33: BM-081 | C33: Cystatin C | D33: 0 | E33: reference_interval | F33: age_19-49J_male | G33: 0.5 | H33: 0.9 | I33: mg/l | J33: mg/L | K33: 19-49 J: m 0,5-0,9 · w 0,53-0,92 · > 49 J: m 0,6-1,0 · w 0,58-1,02 | L33: IMD Berlin | M33: LAB | N33: Leistungsverzeichnis, Stand 12.02.2025 | O33: https://www.imd-berlin.de/fileadmin/user_upload/leistungsverzeichnis_druck/imd_leistungsverzeichnis_2025-03-06.pdf | P33: 2026-07-12 | Q33: IMD-LV-2025 | R33: structured
A34: RI-033 | B34: BM-081 | C34: Cystatin C | D34: 0 | E34: reference_interval | F34: female | G34: 0.53 | H34: 0.92 | I34: mg/l | J34: mg/L | K34: 19-49 J: m 0,5-0,9 · w 0,53-0,92 · > 49 J: m 0,6-1,0 · w 0,58-1,02 | L34: IMD Berlin | M34: LAB | N34: Leistungsverzeichnis, Stand 12.02.2025 | O34: https://www.imd-berlin.de/fileadmin/user_upload/leistungsverzeichnis_druck/imd_leistungsverzeichnis_2025-03-06.pdf | P34: 2026-07-12 | Q34: IMD-LV-2025 | R34: structured
A35: RI-034 | B35: BM-081 | C35: Cystatin C | D35: 0 | E35: reference_interval | F35: age_>49J_male | G35: 0.6 | H35: 1 | I35: mg/l | J35: mg/L | K35: 19-49 J: m 0,5-0,9 · w 0,53-0,92 · > 49 J: m 0,6-1,0 · w 0,58-1,02 | L35: IMD Berlin | M35: LAB | N35: Leistungsverzeichnis, Stand 12.02.2025 | O35: https://www.imd-berlin.de/fileadmin/user_upload/leistungsverzeichnis_druck/imd_leistungsverzeichnis_2025-03-06.pdf | P35: 2026-07-12 | Q35: IMD-LV-2025 | R35: structured
A36: RI-035 | B36: BM-081 | C36: Cystatin C | D36: 0 | E36: reference_interval | F36: female | G36: 0.58 | H36: 1.02 | I36: mg/l | J36: mg/L | K36: 19-49 J: m 0,5-0,9 · w 0,53-0,92 · > 49 J: m 0,6-1,0 · w 0,58-1,02 | L36: IMD Berlin | M36: LAB | N36: Leistungsverzeichnis, Stand 12.02.2025 | O36: https://www.imd-berlin.de/fileadmin/user_upload/leistungsverzeichnis_druck/imd_leistungsverzeichnis_2025-03-06.pdf | P36: 2026-07-12 | Q36: IMD-LV-2025 | R36: structured
A37: RI-036 | B37: BM-087 | C37: DHEA-S | D37: 1 | E37: reference_interval | F37: age_24-34J_male | G37: 1600 | H37: 4490 | I37: ng/ml | J37: ng/mL | K37: 24-34 J: m 1600-4490 · w 988-3400 · 34-44 J: m 889-4720 · w 609-3370 (altersgestaffelt) | L37: IMD Berlin | M37: LAB | N37: Leistungsverzeichnis, Stand 12.02.2025 | O37: https://www.imd-berlin.de/fileadmin/user_upload/leistungsverzeichnis_druck/imd_leistungsverzeichnis_2025-03-06.pdf | P37: 2026-07-12 | Q37: IMD-LV-2025 | R37: structured
A38: RI-037 | B38: BM-087 | C38: DHEA-S | D38: 1 | E38: reference_interval | F38: female | G38: 988 | H38: 3400 | I38: ng/ml | J38: ng/mL | K38: 24-34 J: m 1600-4490 · w 988-3400 · 34-44 J: m 889-4720 · w 609-3370 (altersgestaffelt) | L38: IMD Berlin | M38: LAB | N38: Leistungsverzeichnis, Stand 12.02.2025 | O38: https://www.imd-berlin.de/fileadmin/user_upload/leistungsverzeichnis_druck/imd_leistungsverzeichnis_2025-03-06.pdf | P38: 2026-07-12 | Q38: IMD-LV-2025 | R38: structured
A39: RI-038 | B39: BM-087 | C39: DHEA-S | D39: 1 | E39: reference_interval | F39: age_34-44J_male | G39: 889 | H39: 4720 | I39: ng/ml | J39: ng/mL | K39: 24-34 J: m 1600-4490 · w 988-3400 · 34-44 J: m 889-4720 · w 609-3370 (altersgestaffelt) | L39: IMD Berlin | M39: LAB | N39: Leistungsverzeichnis, Stand 12.02.2025 | O39: https://www.imd-berlin.de/fileadmin/user_upload/leistungsverzeichnis_druck/imd_leistungsverzeichnis_2025-03-06.pdf | P39: 2026-07-12 | Q39: IMD-LV-2025 | R39: structured
A40: RI-039 | B40: BM-090 | C40: ECP | D40: 0 | E40: reference_interval | F40: general_adult | H40: 13.3 | I40: µg/l | J40: ug/L | K40: < 13,3 | L40: IMD Berlin | M40: LAB | N40: Leistungsverzeichnis, Stand 12.02.2025 | O40: https://www.imd-berlin.de/fileadmin/user_upload/leistungsverzeichnis_druck/imd_leistungsverzeichnis_2025-03-06.pdf | P40: 2026-07-12 | Q40: IMD-LV-2025 | R40: structured
...

Sheet LOINC_Map
A1: biomarker_id | B1: name_de | C1: loinc_code | D1: loinc_name | E1: loinc_status | F1: unit_canonical | G1: in_core_set | H1: loinc_url | I1: review_record_status | J1: review_record_path
A2: BM-001 | B2: 17-Beta-Östradiol | C2: 14715-7 | D2: Estradiol (E2) [Moles/volume] in Serum or Plasma | E2: validated | F2: pmol/l | G2: 1 | H2: https://loinc.org/14715-7 | I2: UNVERIFIED | J2: docs/terminology/review-records/14715-7.md
A3: BM-014 | B3: Anti-Müller-Hormon (AMH) | C3: 83104-0 | D3: Mullerian inhibiting substance [Mass/volume] in Serum or Plasma by Immunoassay | E3: validated | F3: ng/ml | G3: 1 | H3: https://loinc.org/83104-0 | I3: UNVERIFIED | J3: docs/terminology/review-records/83104-0.md
A4: BM-057 | B4: Biotin (Vitamin B7) | C4: 1980-2 | D4: Biotin [Mass/volume] in Serum or Plasma | E4: validated | F4: ng/l | G4: 1 | H4: https://loinc.org/1980-2 | I4: UNVERIFIED | J4: docs/terminology/review-records/1980-2.md
A5: BM-060 | B5: Bor | C5: 52914-9 | D5: Boron [Moles/volume] in Serum or Plasma | E5: validated | F5: µg/l | G5: 1 | H5: https://loinc.org/52914-9 | I5: UNVERIFIED | J5: docs/terminology/review-records/52914-9.md
A6: BM-063 | B6: Calcium | C6: 2000-8 | D6: Calcium [Moles/volume] in Serum or Plasma | E6: validated | F6: mmol/l | G6: 1 | H6: https://loinc.org/2000-8 | I6: UNVERIFIED | J6: docs/terminology/review-records/2000-8.md
A7: BM-064 | B7: Calprotectin | C7: 38445-3 | D7: Calprotectin [Mass/mass] in Stool | E7: validated | F7: µg/g | G7: 1 | H7: https://loinc.org/38445-3 | I7: UNVERIFIED | J7: docs/terminology/review-records/38445-3.md
A8: BM-072 | B8: Cholesterin (gesamt) | C8: 2093-3 | D8: Cholesterol [Mass/volume] in Serum or Plasma | E8: validated | F8: mg/dl | G8: 1 | H8: https://loinc.org/2093-3 | I8: UNVERIFIED | J8: docs/terminology/review-records/2093-3.md
A9: BM-077 | B9: Cortisol | C9: 2143-6 | D9: Cortisol [Mass/volume] in Serum or Plasma | E9: validated | F9: ng/ml | G9: 1 | H9: https://loinc.org/2143-6 | I9: UNVERIFIED | J9: docs/terminology/review-records/2143-6.md
A10: BM-078 | B10: Creatinkinase (CK) | C10: 2157-6 | D10: Creatine kinase [Enzymatic activity/volume] in Serum or Plasma | E10: validated | F10: U/l | G10: 1 | H10: https://loinc.org/2157-6 | I10: UNVERIFIED | J10: docs/terminology/review-records/2157-6.md
A11: BM-079 | B11: CRP (hochsensitiv) | C11: 30522-7 | D11: C reactive protein [Mass/volume] in Serum or Plasma by High sensitivity method | E11: validated | F11: mg/l | G11: 1 | H11: https://loinc.org/30522-7 | I11: UNVERIFIED | J11: docs/terminology/review-records/30522-7.md
A12: BM-087 | B12: DHEA-S | C12: 2191-5 | D12: Dehydroepiandrosterone sulfate [Mass/volume] in Serum or Plasma | E12: validated | F12: ng/ml | G12: 1 | H12: https://loinc.org/2191-5 | I12: UNVERIFIED | J12: docs/terminology/review-records/2191-5.md
A13: BM-107 | B13: Ferritin | C13: 2276-4 | D13: Ferritin [Mass/volume] in Serum or Plasma | E13: validated | F13: ng/ml | G13: 1 | H13: https://loinc.org/2276-4 | I13: UNVERIFIED | J13: docs/terminology/review-records/2276-4.md
... A68: BM-436 | B68: Kreatinin | C68: 2160-0 | D68: Creatinine [Mass/volume] in Serum or Plasma | E68: validated | F68: mg/dl | G68: 1 | H68: https://loinc.org/2160-0 | I68: UNVERIFIED | J68: docs/terminology/review-records/2160-0.md
I69: UNVERIFIED | J69: docs/terminology/review-records/nan.md
A70: VALIDATION COMPLETE: All Anchor core-set LOINC codes verified on loinc.org. Non-core biomarkers are out_of_scope for LOINC in this deliverable. | I70: UNVERIFIED | J70: docs/terminology/review-records/nan.md
A72: Every code here is UNVERIFIED. Per the project rule, a code enters the repo only through a signed review record naming the reviewer, the source URL and the retrieval date. An AI check does not count.

Sheet Data_Quality_Findings
A1: finding_id | B1: area | C1: severity | D1: description | E1: proposed_resolution | F1: owner | G1: status
A2: F-01 | B2: Terminology | C2: BLOCKING | D2: BM-060 Bor sits on LOINC 52914-9 Boron [Moles/volume] but the unit is ug/L (mass). | E2: Re-code to a mass-property LOINC, or convert at ingestion. Recommend re-code. | F2: Martin / clinical reviewer | G2: OPEN
A3: F-02 | B3: Terminology | C3: BLOCKING | D3: BM-186 Kupfer sits on LOINC 14665-4 Copper [Moles/volume] but the unit is ug/L (mass). | E3: As F-01. | F3: Martin / clinical reviewer | G3: OPEN
A4: F-03 | B4: Terminology | C4: BLOCKING | D4: BM-405 Vitamin K sits on LOINC 58793-1 Phytonadione [Moles/volume] but the unit is ng/L (mass). | E4: As F-01. | F4: Martin / clinical reviewer | G4: OPEN
A5: F-04 | B5: Data pipeline | C5: HIGH | D5: FineTuned workbook lost the parsed low/high/population columns in Reference_Intervals: 98 populated rows became 0. Only free German prose remains. | E5: Restored in this file from the 2026-07-27 workbook. Fix the builder so the parse survives export. | F5: Peter | G5: RESOLVED_IN_THIS_FILE
A6: F-05 | B6: Data pipeline | C6: MEDIUM | D6: FineTuned Reference_Intervals dropped from 100 rows to 70. | E6: Restored from the 2026-07-27 workbook. | F6: Peter | G6: RESOLVED_IN_THIS_FILE
A7: F-06 | B7: Terminology | C7: HIGH | D7: All units were in German or local notation. G/l and T/l in particular mean 10*9/L and 10*12/L, not gauss and tesla per litre. | E7: unit_ucum column added for all 67. Must still be validated against a real UCUM grammar library in CI. | F7: Peter | G7: RESOLVED_IN_THIS_FILE
A8: F-07 | B8: Semantics | C8: HIGH | D8: organ_mapping was free text: 26 tokens, comma separated, no controlled vocabulary and no ontology binding. | E8: Closed 25-value region enum added on the Region_Enum sheet, plus a token crosswalk. | F8: Peter, confirm with Martin | G8: PROPOSED
A9: F-08 | B9: Semantics | C9: MEDIUM | D9: Four markers had no clean region target: BM-128 Glukose, BM-125 Gesamteiweiss, BM-156 Homocystein, BM-258 Magnesium. | E9: Overrides applied and flagged in the region_assignment column. Each needs confirming. | F9: Clinical reviewer | G9: OPEN
A10: F-09 | B10: Semantics | C10: LOW | D10: Three tokens carry no locational information: Systemic, Endocrine, Metabolic. | E10: Retire. See Organ_Mapping_Crosswalk. | F10: Peter | G10: PROPOSED
A11: F-10 | B11: Evidence | C11: MEDIUM | D11: The G-I-N RIS export is malformed. TY is used as a keyword field, UR holds a region name, AU holds emails and years. A standard parser produces nonsense. | E11: Re-export or convert to a JSON index with stable citation ids before the rule pack cites it. | F11: Peter | G11: OPEN
A12: F-11 | B12: Method | C12: LOW | D12: SAD Figure 11 shows Core tier 1 N=36 and Excluded 9. The workbook shows 35 and 10, with the Kreatinin panel moved to decomposition. | E12: Workbook is the later artefact. Update Figure 11 so the two agree. | F12: Peter | G12: OPEN
... A17: F-15 | B17: Data model | C17: MEDIUM | D17: Five rows in Reference_Intervals are interpretive bands (optimal, gut, grenzwertig, erhoeht, pathologisch), not reference intervals. They are already an interpretation. | E17: Tagged in the new record_kind column. Do not load them into the same field as measured intervals. | F17: Peter | G17: RESOLVED_IN_THIS_FILE

Sheet C3_Audit
A1: biomarker_id | B1: name_de | C1: c3_pass | D1: selection_status | E1: in_core_set | F1: guideline_evidence | G1: guideline_url
A2: BM-014 | B2: Anti-Müller-Hormon (AMH) | C2: =TRUE() -> TRUE | D2: core_tier2 | E2: =TRUE() -> TRUE | F2: NICE NG257 Fertility problems (2026): use AMH measurement as predictor of ovarian response in assisted conception | G2: https://www.nice.org.uk/guidance/ng257
A3: BM-057 | B3: Biotin (Vitamin B7) | C3: =TRUE() -> TRUE | D3: core_tier2 | E3: =TRUE() -> TRUE | F3: ESPEN micronutrient guideline Rec 19.2 (via AWMF 073-019 deferral): biotin status by direct blood/urine biotin + biotinidase | G3: https://doi.org/10.1016/j.clnu.2024.01.030
A4: BM-064 | B4: Calprotectin | C4: =TRUE() -> TRUE | D4: core_tier2 | E4: =TRUE() -> TRUE | F4: NICE DG11 Faecal calprotectin diagnostic tests for inflammatory diseases of the bowel | G4: https://www.nice.org.uk/guidance/dg11
A5: BM-076 | B5: Coenzym Q10 | C5: =FALSE() -> FALSE | D5: excluded_C3 | E5: =FALSE() -> FALSE | F5: No GIN-listed CPG names plasma/serum CoQ10 as a diagnostic measured parameter; ESPEN lists CoQ10 under non-DRI nutrients
A6: BM-078 | B6: Creatinkinase (CK) | C6: =TRUE() -> TRUE | D6: core_tier2 | E6: =TRUE() -> TRUE | F6: NICE NG238 CVD risk / lipid modification: measure creatine kinase before/on statin if unexplained muscle symptoms | G6: https://www.nice.org.uk/guidance/ng238
A7: BM-119 | B7: FSH | C7: =TRUE() -> TRUE | D7: core_tier2 | E7: =TRUE() -> TRUE | F7: NICE NG257: offer blood test to measure serum gonadotrophins (FSH and LH) in irregular cycles | G7: https://www.nice.org.uk/guidance/ng257
A8: BM-125 | B8: Gesamteiweiß | C8: =TRUE() -> TRUE | D8: core_tier2 | E8: =TRUE() -> TRUE | F8: AWMF 021-021 S2k Zöliakie: screen for Eiweiß (Hypoproteinämie) among deficiency parameters | G8: https://register.awmf.org/de/leitlinien/detail/021-021
A9: BM-136 | B9: Harnsäure | C9: =TRUE() -> TRUE | D9: core_tier2 | E9: =TRUE() -> TRUE | F9: NICE NG219 Gout: measure serum urate to confirm diagnosis and for ULT monitoring | G9: https://www.nice.org.uk/guidance/ng219
A10: BM-156 | B10: Homocystein | C10: =TRUE() -> TRUE | D10: core_tier2 | E10: =TRUE() -> TRUE | F10: NICE NG239 Vitamin B12 deficiency: measure plasma homocysteine | G10: https://www.nice.org.uk/guidance/ng239
A11: BM-197 | B11: LH | C11: =TRUE() -> TRUE | D11: core_tier2 | E11: =TRUE() -> TRUE | F11: NICE NG257: offer blood test to measure serum gonadotrophins (FSH and LH) in irregular cycles | G11: https://www.nice.org.uk/guidance/ng257
A12: BM-292 | B12: Omega-3-Fettsäuren | C12: =FALSE() -> FALSE | D12: excluded_C3 | E12: =FALSE() -> FALSE | F12: No NICE/AWMF/WHO/SIGN CPG names blood omega-3 index / fatty-acid panel as a measured clinical parameter
A13: BM-312 | B13: Prolaktin | C13: =TRUE() -> TRUE | D13: core_tier2 | E13: =TRUE() -> TRUE | F13: NICE NG257: measure prolactin when ovulatory disorder, galactorrhoea, or suspected pituitary tumour | G13: https://www.nice.org.uk/guidance/ng257
A14: BM-315 | B14: PSA | C14: =TRUE() -> TRUE | D14: core_tier2 | E14: =TRUE() -> TRUE | F14: NICE NG131 Prostate cancer: measure PSA for diagnosis pathway, active surveillance, and follow-up | G14: https://www.nice.org.uk/guidance/ng131
A15: BM-392 | B15: Vitamin A | C15: =TRUE() -> TRUE | D15: core_tier2 | E15: =TRUE() -> TRUE | F15: WHO NMH/NHD/MNM/11.3 serum retinol; ESPEN Rec 22.2: determine status by measuring serum retinol | G15: https://www.who.int/publications/i/item/WHO-NMH-NHD-MNM-11.3
